Workbook

Sheet Parameters
A1: LCOH MODEL — On-Site HRS Techno-Economic Analysis
A2: Kuhyar Saeedi | Clean Hydrogen Technologies | A.Y. 2025/2026
A3: Blue = input you can change | Black = calculated | Based on Minutillo et al. (2021) + instructor simplifications S1–S4
A5: A. GENERAL
A6: Plant lifetime n | B6: 20 | C6: years | D6: Minutillo 2021, Table 5
A7: Nominal interest rate i | B7: 0.03 | C7: - | D7: Minutillo 2021, Table 5
A8: Capital Recovery Factor CRF | B8: =B7*(1+B7)^B6/((1+B7)^B6-1) -> 0.067215708 | C8: - | D8: CRF = i(1+i)^n/((1+i)^n-1)
A9: Operating days per year | B9: 365 | C9: days | D9: Continuous 24h operation
A10: Operating hours per year | B10: =B9*24 -> 8760 | C10: h | D10: days x 24
A11: B. ELECTROLYZER (Alkaline)
A12: H2 production per module | B12: 50 | C12: kg/day | D12: Minutillo 2021
A13: H2 flow rate per module | B13: 23 | C13: Nm3/h | D13: Minutillo 2021
A14: Nominal power per module | B14: 118 | C14: kW | D14: Minutillo 2021
A15: Specific consumption (baseline) | B15: 5.1 | C15: kWh/Nm3 | D15: Minutillo 2021
A16: H2 density | B16: 0.089 | C16: kg/Nm3 | D16: Standard
A17: LHV of hydrogen | B17: 33 | C17: kWh/kg | D17: Standard
A18: Electrolyzer efficiency | B18: =B17/(B15/B16) -> 0.57588235 | C18: - | D18: eta = LHV/(spec/density)
A19: Electrolyzer cost | B19: 1100 | C19: EUR/kW | D19: Minutillo 2021, Table 5
A20: O&M electrolyzer | B20: 0.02 | C20: frac CAPEX/yr | D20: Table 5
A21: Replacement factor electrolyzer | B21: 0.405 | C21: frac CAPEX | D21: ~52.6/129.8 (paper)
A22: C. COMPRESSION (isentropic)
A23: Ratio of specific heats k | B23: 1.4 | C23: - | D23: Standard for H2
A24: Gas constant R_H2 | B24: 4.12 | C24: kJ/kg.K | D24: Standard for H2
A25: Inlet temperature | B25: 298 | C25: K | D25: 25 C
A26: Inlet pressure | B26: 10 | C26: bar | D26: Electrolysis outlet
A27: Outlet pressure | B27: 820 | C27: bar | D27: Cascade filling
A28: Isentropic efficiency | B28: 0.8 | C28: - | D28: Minutillo 2021
A29: Mechanical efficiency | B29: 0.98 | C29: - | D29: Minutillo 2021
A30: Generator efficiency | B30: 0.96 | C30: - | D30: Minutillo 2021
A31: Compression work per kg | B31: =B23/(B23-1)*B24*B25*((B27/B26)^((B23-1)/B23)-1)/(B28*B29*B30) -> 14399.908 | C31: kJ/kg | D31: Isentropic /effs
A32: Compressor cost constant | B32: 43872 | C32: EUR | D32: c = k x P^exp
A33: Compressor cost exponent | B33: 0.5861 | C33: - | D33: Table 5
A34: O&M compressor | B34: 0.08 | C34: frac CAPEX/yr | D34: Table 5
A35: D. REFRIGERATION
A36: Enthalpy difference dh | B36: 976.8 | C36: kJ/kg | D36: REFPROP 25->-40 C
A37: H2 flow at dispenser | B37: 0.0167 | C37: kg/s | D37: Minutillo 2021
A38: COP of refrigerator | B38: 1 | C38: - | D38: Minutillo 2021
A39: Refrigerator cost | B39: 5374 | C39: EUR/kW | D39: Table 5
A40: O&M refrigerator | B40: 0.03 | C40: frac CAPEX/yr | D40: Table 5
A41: E. DISPENSER
...

Sheet Model_Naples
A1: MODEL — South Italy (Naples), yield 1272 kWh/kWp/yr
A2: 12 configurations — all values live-linked to Parameters sheet
A4: Config | B4: Size | C4: N_mod | D4: N_disp | E4: Grid frac | F4: kg/day | G4: H2 [kg/yr] | H4: E_elec [MWh] | I4: E_total [MWh] | J4: E_grid [MWh] | K4: E_PV [MWh] | L4: PV [kWp] | M4: Comp [kW] | N4: Refrig [kW] | O4: CX Elec [k€] | P4: CX Comp [k€] | Q4: CX Refrig [k€] | R4: CX Disp [k€] | S4: CX Water [k€] | T4: CX PV [k€] | U4: CAPEX [k€] | V4: Elec price [€/MWh] | W4: Elec cost [k€/yr] | X4: O&M tot [k€/yr] | Y4: OPEX [k€/yr] | Z4: C_inv,a [k€/yr] | AA4: C_rep,a [k€/yr] | AB4: Total [k€/yr] | AC4: LCOH [€/kg]
A5: Micro_FG | B5: Micro | C5: 1 | D5: 1 | E5: 1 | F5: =C5*Parameters!$B$12 -> 50 | G5: =F5*Parameters!$B$9 -> 18250 | H5: =C5*Parameters!$B$14*Parameters!$B$10/1000 -> 1033.68 | I5: =H5/Parameters!$B$55 -> 1148.5333 | J5: =I5*E5 -> 1148.5333 | K5: =I5*(1-E5) -> 0 | L5: =K5*1000/Parameters!$B$50 -> 0 | M5: =C5*(Parameters!$B$12/86400)*Parameters!$B$31 -> 8.3332799 | N5: =D5*Parameters!$B$37*Parameters!$B$36/Parameters!$B$38 -> 16.31256 | O5: =C5*Parameters!$B$14*Parameters!$B$19/1000 -> 129.8 | P5: =Parameters!$B$32*M5^Parameters!$B$33/1000 -> 152.01193 | Q5: =N5*Parameters!$B$39/1000 -> 87.663697 | R5: =D5*Parameters!$B$42/1000 -> 65 | S5: =C5*Parameters!$B$14*Parameters!$B$45/1000 -> 0.99946 | T5: =L5*Parameters!$B$48/1000 -> 0 | U5: =O5+P5+Q5+R5+S5+T5 -> 435.47509 | V5: =IF(C5=1,Parameters!$B$52,IF(C5=2,Parameters!$B$53,Parameters!$B$54)) -> 129 | W5: =J5*V5/1000 -> 148.1608 | X5: =O5*Parameters!$B$20+P5*Parameters!$B$34+Q5*Parameters!$B$40+R5*Parameters!$B$43+S5*Parameters!$B$46+T5*Parameters!$B$49 -> 19.356855 | Y5: =W5+X5 -> 167.51765 | Z5: =U5*Parameters!$B$8 -> 29.270766 | AA5: =Parameters!$B$8*((Parameters!$B$21*O5+P5+R5+S5)/(1+Parameters!$B$7)^10+Q5/(1+Parameters!$B$7)^15) -> 17.315117 | AB5: =Y5+Z5+AA5 -> 214.10354 | AC5: =AB5*1000/G5 -> 11.731701
A6: Micro_HG | B6: Micro | C6: 1 | D6: 1 | E6: 0.75 | F6: =C6*Parameters!$B$12 -> 50 | G6: =F6*Parameters!$B$9 -> 18250 | H6: =C6*Parameters!$B$14*Parameters!$B$10/1000 -> 1033.68 | I6: =H6/Parameters!$B$55 -> 1148.5333 | J6: =I6*E6 -> 861.4 | K6: =I6*(1-E6) -> 287.13333 | L6: =K6*1000/Parameters!$B$50 -> 191.80583 | M6: =C6*(Parameters!$B$12/86400)*Parameters!$B$31 -> 8.3332799 | N6: =D6*Parameters!$B$37*Parameters!$B$36/Parameters!$B$38 -> 16.31256 | O6: =C6*Parameters!$B$14*Parameters!$B$19/1000 -> 129.8 | P6: =Parameters!$B$32*M6^Parameters!$B$33/1000 -> 152.01193 | Q6: =N6*Parameters!$B$39/1000 -> 87.663697 | R6: =D6*Parameters!$B$42/1000 -> 65 | S6: =C6*Parameters!$B$14*Parameters!$B$45/1000 -> 0.99946 | T6: =L6*Parameters!$B$48/1000 -> 182.21554 | U6: =O6+P6+Q6+R6+S6+T6 -> 617.69063 | V6: =IF(C6=1,Parameters!$B$52,IF(C6=2,Parameters!$B$53,Parameters!$B$54)) -> 129 | W6: =J6*V6/1000 -> 111.1206 | X6: =O6*Parameters!$B$20+P6*Parameters!$B$34+Q6*Parameters!$B$40+R6*Parameters!$B$43+S6*Parameters!$B$46+T6*Parameters!$B$49 -> 22.23586 | Y6: =W6+X6 -> 133.35646 | Z6: =U6*Parameters!$B$8 -> 41.518513 | AA6: =Parameters!$B$8*((Parameters!$B$21*O6+P6+R6+S6)/(1+Parameters!$B$7)^10+Q6/(1+Parameters!$B$7)^15) -> 17.315117 | AB6: =Y6+Z6+AA6 -> 192.19009 | AC6: =AB6*1000/G6 -> 10.530964
A7: Micro_MG | B7: Micro | C7: 1 | D7: 1 | E7: 0.5 | F7: =C7*Parameters!$B$12 -> 50 | G7: =F7*Parameters!$B$9 -> 18250 | H7: =C7*Parameters!$B$14*Parameters!$B$10/1000 -> 1033.68 | I7: =H7/Parameters!$B$55 -> 1148.5333 | J7: =I7*E7 -> 574.26667 | K7: =I7*(1-E7) -> 574.26667 | L7: =K7*1000/Parameters!$B$50 -> 383.61167 | M7: =C7*(Parameters!$B$12/86400)*Parameters!$B$31 -> 8.3332799 | N7: =D7*Parameters!$B$37*Parameters!$B$36/Parameters!$B$38 -> 16.31256 | O7: =C7*Parameters!$B$14*Parameters!$B$19/1000 -> 129.8 | P7: =Parameters!$B$32*M7^Parameters!$B$33/1000 -> 152.01193 | Q7: =N7*Parameters!$B$39/1000 -> 87.663697 | R7: =D7*Parameters!$B$42/1000 -> 65 | S7: =C7*Parameters!$B$14*Parameters!$B$45/1000 -> 0.99946 | T7: =L7*Parameters!$B$48/1000 -> 364.43108 | U7: =O7+P7+Q7+R7+S7+T7 -> 799.90617 | V7: =IF(C7=1,Parameters!$B$52,IF(C7=2,Parameters!$B$53,Parameters!$B$54)) -> 129 | W7: =J7*V7/1000 -> 74.0804 | X7: =O7*Parameters!$B$20+P7*Parameters!$B$34+Q7*Parameters!$B$40+R7*Parameters!$B$43+S7*Parameters!$B$46+T7*Parameters!$B$49 -> 25.114866 | Y7: =W7+X7 -> 99.195266 | Z7: =U7*Parameters!$B$8 -> 53.766259 | AA7: =Parameters!$B$8*((Parameters!$B$21*O7+P7+R7+S7)/(1+Parameters!$B$7)^10+Q7/(1+Parameters!$B$7)^15) -> 17.315117 | AB7: =Y7+Z7+AA7 -> 170.27664 | AC7: =AB7*1000/G7 -> 9.3302269
A8: Micro_LG | B8: Micro | C8: 1 | D8: 1 | E8: 0.25 | F8: =C8*Parameters!$B$12 -> 50 | G8: =F8*Parameters!$B$9 -> 18250 | H8: =C8*Parameters!$B$14*Parameters!$B$10/1000 -> 1033.68 | I8: =H8/Parameters!$B$55 -> 1148.5333 | J8: =I8*E8 -> 287.13333 | K8: =I8*(1-E8) -> 861.4 | L8: =K8*1000/Parameters!$B$50 -> 575.4175 | M8: =C8*(Parameters!$B$12/86400)*Parameters!$B$31 -> 8.3332799 | N8: =D8*Parameters!$B$37*Parameters!$B$36/Parameters!$B$38 -> 16.31256 | O8: =C8*Parameters!$B$14*Parameters!$B$19/1000 -> 129.8 | P8: =Parameters!$B$32*M8^Parameters!$B$33/1000 -> 152.01193 | Q8: =N8*Parameters!$B$39/1000 -> 87.663697 | R8: =D8*Parameters!$B$42/1000 -> 65 | S8: =C8*Parameters!$B$14*Parameters!$B$45/1000 -> 0.99946 | T8: =L8*Parameters!$B$48/1000 -> 546.64663 | U8: =O8+P8+Q8+R8+S8+T8 -> 982.12171 | V8: =IF(C8=1,Parameters!$B$52,IF(C8=2,Parameters!$B$53,Parameters!$B$54)) -> 129 | W8: =J8*V8/1000 -> 37.0402 | X8: =O8*Parameters!$B$20+P8*Parameters!$B$34+Q8*Parameters!$B$40+R8*Parameters!$B$43+S8*Parameters!$B$46+T8*Parameters!$B$49 -> 27.993871 | Y8: =W8+X8 -> 65.034071 | Z8: =U8*Parameters!$B$8 -> 66.014006 | AA8: =Parameters!$B$8*((Parameters!$B$21*O8+P8+R8+S8)/(1+Parameters!$B$7)^10+Q8/(1+Parameters!$B$7)^15) -> 17.315117 | AB8: =Y8+Z8+AA8 -> 148.36319 | AC8: =AB8*1000/G8 -> 8.1294901
A9: Small_FG | B9: Small | C9: 2 | D9: 2 | E9: 1 | F9: =C9*Parameters!$B$12 -> 100 | G9: =F9*Parameters!$B$9 -> 36500 | H9: =C9*Parameters!$B$14*Parameters!$B$10/1000 -> 2067.36 | I9: =H9/Parameters!$B$55 -> 2297.0667 | J9: =I9*E9 -> 2297.0667 | K9: =I9*(1-E9) -> 0 | L9: =K9*1000/Parameters!$B$50 -> 0 | M9: =C9*(Parameters!$B$12/86400)*Parameters!$B$31 -> 16.66656 | N9: =D9*Parameters!$B$37*Parameters!$B$36/Parameters!$B$38 -> 32.62512 | O9: =C9*Parameters!$B$14*Parameters!$B$19/1000 -> 259.6 | P9: =Parameters!$B$32*M9^Parameters!$B$33/1000 -> 228.19775 | Q9: =N9*Parameters!$B$39/1000 -> 175.32739 | R9: =D9*Parameters!$B$42/1000 -> 130 | S9: =C9*Parameters!$B$14*Parameters!$B$45/1000 -> 1.99892 | T9: =L9*Parameters!$B$48/1000 -> 0 | U9: =O9+P9+Q9+R9+S9+T9 -> 795.12406 | V9: =IF(C9=1,Parameters!$B$52,IF(C9=2,Parameters!$B$53,Parameters!$B$54)) -> 119 | W9: =J9*V9/1000 -> 273.35093 | X9: =O9*Parameters!$B$20+P9*Parameters!$B$34+Q9*Parameters!$B$40+R9*Parameters!$B$43+S9*Parameters!$B$46+T9*Parameters!$B$49 -> 32.64762 | Y9: =W9+X9 -> 305.99855 | Z9: =U9*Parameters!$B$8 -> 53.444826 | AA9: =Parameters!$B$8*((Parameters!$B$21*O9+P9+R9+S9)/(1+Parameters!$B$7)^10+Q9/(1+Parameters!$B$7)^15) -> 30.837806 | AB9: =Y9+Z9+AA9 -> 390.28119 | AC9: =AB9*1000/G9 -> 10.692635
A10: Small_HG | B10: Small | C10: 2 | D10: 2 | E10: 0.75 | F10: =C10*Parameters!$B$12 -> 100 | G10: =F10*Parameters!$B$9 -> 36500 | H10: =C10*Parameters!$B$14*Parameters!$B$10/1000 -> 2067.36 | I10: =H10/Parameters!$B$55 -> 2297.0667 | J10: =I10*E10 -> 1722.8 | K10: =I10*(1-E10) -> 574.26667 | L10: =K10*1000/Parameters!$B$50 -> 383.61167 | M10: =C10*(Parameters!$B$12/86400)*Parameters!$B$31 -> 16.66656 | N10: =D10*Parameters!$B$37*Parameters!$B$36/Parameters!$B$38 -> 32.62512 | O10: =C10*Parameters!$B$14*Parameters!$B$19/1000 -> 259.6 | P10: =Parameters!$B$32*M10^Parameters!$B$33/1000 -> 228.19775 | Q10: =N10*Parameters!$B$39/1000 -> 175.32739 | R10: =D10*Parameters!$B$42/1000 -> 130 | S10: =C10*Parameters!$B$14*Parameters!$B$45/1000 -> 1.99892 | T10: =L10*Parameters!$B$48/1000 -> 364.43108 | U10: =O10+P10+Q10+R10+S10+T10 -> 1159.5551 | V10: =IF(C10=1,Parameters!$B$52,IF(C10=2,Parameters!$B$53,Parameters!$B$54)) -> 119 | W10: =J10*V10/1000 -> 205.0132 | X10: =O10*Parameters!$B$20+P10*Parameters!$B$34+Q10*Parameters!$B$40+R10*Parameters!$B$43+S10*Parameters!$B$46+T10*Parameters!$B$49 -> 38.405631 | Y10: =W10+X10 -> 243.41883 | Z10: =U10*Parameters!$B$8 -> 77.94032 | AA10: =Parameters!$B$8*((Parameters!$B$21*O10+P10+R10+S10)/(1+Parameters!$B$7)^10+Q10/(1+Parameters!$B$7)^15) -> 30.837806 | AB10: =Y10+Z10+AA10 -> 352.19696 | AC10: =AB10*1000/G10 -> 9.6492317
A11: Small_MG | B11: Small | C11: 2 | D11: 2 | E11: 0.5 | F11: =C11*Parameters!$B$12 -> 100 | G11: =F11*Parameters!$B$9 -> 36500 | H11: =C11*Parameters!$B$14*Parameters!$B$10/1000 -> 2067.36 | I11: =H11/Parameters!$B$55 -> 2297.0667 | J11: =I11*E11 -> 1148.5333 | K11: =I11*(1-E11) -> 1148.5333 | L11: =K11*1000/Parameters!$B$50 -> 767.22334 | M11: =C11*(Parameters!$B$12/86400)*Parameters!$B$31 -> 16.66656 | N11: =D11*Parameters!$B$37*Parameters!$B$36/Parameters!$B$38 -> 32.62512 | O11: =C11*Parameters!$B$14*Parameters!$B$19/1000 -> 259.6 | P11: =Parameters!$B$32*M11^Parameters!$B$33/1000 -> 228.19775 | Q11: =N11*Parameters!$B$39/1000 -> 175.32739 | R11: =D11*Parameters!$B$42/1000 -> 130 | S11: =C11*Parameters!$B$14*Parameters!$B$45/1000 -> 1.99892 | T11: =L11*Parameters!$B$48/1000 -> 728.86217 | U11: =O11+P11+Q11+R11+S11+T11 -> 1523.9862 | V11: =IF(C11=1,Parameters!$B$52,IF(C11=2,Parameters!$B$53,Parameters!$B$54)) -> 119 | W11: =J11*V11/1000 -> 136.67547 | X11: =O11*Parameters!$B$20+P11*Parameters!$B$34+Q11*Parameters!$B$40+R11*Parameters!$B$43+S11*Parameters!$B$46+T11*Parameters!$B$49 -> 44.163642 | Y11: =W11+X11 -> 180.83911 | Z11: =U11*Parameters!$B$8 -> 102.43581 | AA11: =Parameters!$B$8*((Parameters!$B$21*O11+P11+R11+S11)/(1+Parameters!$B$7)^10+Q11/(1+Parameters!$B$7)^15) -> 30.837806 | AB11: =Y11+Z11+AA11 -> 314.11273 | AC11: =AB11*1000/G11 -> 8.6058282
A12: Small_LG | B12: Small | C12: 2 | D12: 2 | E12: 0.25 | F12: =C12*Parameters!$B$12 -> 100 | G12: =F12*Parameters!$B$9 -> 36500 | H12: =C12*Parameters!$B$14*Parameters!$B$10/1000 -> 2067.36 | I12: =H12/Parameters!$B$55 -> 2297.0667 | J12: =I12*E12 -> 574.26667 | K12: =I12*(1-E12) -> 1722.8 | L12: =K12*1000/Parameters!$B$50 -> 1150.835 | M12: =C12*(Parameters!$B$12/86400)*Parameters!$B$31 -> 16.66656 | N12: =D12*Parameters!$B$37*Parameters!$B$36/Parameters!$B$38 -> 32.62512 | O12: =C12*Parameters!$B$14*Parameters!$B$19/1000 -> 259.6 | P12: =Parameters!$B$32*M12^Parameters!$B$33/1000 -> 228.19775 | Q12: =N12*Parameters!$B$39/1000 -> 175.32739 | R12: =D12*Parameters!$B$42/1000 -> 130 | S12: =C12*Parameters!$B$14*Parameters!$B$45/1000 -> 1.99892 | T12: =L12*Parameters!$B$48/1000 -> 1093.2933 | U12: =O12+P12+Q12+R12+S12+T12 -> 1888.4173 | V12: =IF(C12=1,Parameters!$B$52,IF(C12=2,Parameters!$B$53,Parameters!$B$54)) -> 119 | W12: =J12*V12/1000 -> 68.337733 | X12: =O12*Parameters!$B$20+P12*Parameters!$B$34+Q12*Parameters!$B$40+R12*Parameters!$B$43+S12*Parameters!$B$46+T12*Parameters!$B$49 -> 49.921653 | Y12: =W12+X12 -> 118.25939 | Z12: =U12*Parameters!$B$8 -> 126.93131 | AA12: =Parameters!$B$8*((Parameters!$B$21*O12+P12+R12+S12)/(1+Parameters!$B$7)^10+Q12/(1+Parameters!$B$7)^15) -> 30.837806 | AB12: =Y12+Z12+AA12 -> 276.0285 | AC12: =AB12*1000/G12 -> 7.5624246
A13: Medium_FG | B13: Medium | C13: 4 | D13: 2 | E13: 1 | F13: =C13*Parameters!$B$12 -> 200 | G13: =F13*Parameters!$B$9 -> 73000 | H13: =C13*Parameters!$B$14*Parameters!$B$10/1000 -> 4134.72 | I13: =H13/Parameters!$B$55 -> 4594.1333 | J13: =I13*E13 -> 4594.1333 | K13: =I13*(1-E13) -> 0 | L13: =K13*1000/Parameters!$B$50 -> 0 | M13: =C13*(Parameters!$B$12/86400)*Parameters!$B$31 -> 33.33312 | N13: =D13*Parameters!$B$37*Parameters!$B$36/Parameters!$B$38 -> 32.62512 | O13: =C13*Parameters!$B$14*Parameters!$B$19/1000 -> 519.2 | P13: =Parameters!$B$32*M13^Parameters!$B$33/1000 -> 342.56661 | Q13: =N13*Parameters!$B$39/1000 -> 175.32739 | R13: =D13*Parameters!$B$42/1000 -> 130 | S13: =C13*Parameters!$B$14*Parameters!$B$45/1000 -> 3.99784 | T13: =L13*Parameters!$B$48/1000 -> 0 | U13: =O13+P13+Q13+R13+S13+T13 -> 1171.0918 | V13: =IF(C13=1,Parameters!$B$52,IF(C13=2,Parameters!$B$53,Parameters!$B$54)) -> 109 | W13: =J13*V13/1000 -> 500.76053 | X13: =O13*Parameters!$B$20+P13*Parameters!$B$34+Q13*Parameters!$B$40+R13*Parameters!$B$43+S13*Parameters!$B$46+T13*Parameters!$B$49 -> 47.029108 | Y13: =W13+X13 -> 547.78964 | Z13: =U13*Parameters!$B$8 -> 78.715767 | AA13: =Parameters!$B$8*((Parameters!$B$21*O13+P13+R13+S13)/(1+Parameters!$B$7)^10+Q13/(1+Parameters!$B$7)^15) -> 41.916373 | AB13: =Y13+Z13+AA13 -> 668.42178 | AC13: =AB13*1000/G13 -> 9.1564628
A14: Medium_HG | B14: Medium | C14: 4 | D14: 2 | E14: 0.75 | F14: =C14*Parameters!$B$12 -> 200 | G14: =F14*Parameters!$B$9 -> 73000 | H14: =C14*Parameters!$B$14*Parameters!$B$10/1000 -> 4134.72 | I14: =H14/Parameters!$B$55 -> 4594.1333 | J14: =I14*E14 -> 3445.6 | K14: =I14*(1-E14) -> 1148.5333 | L14: =K14*1000/Parameters!$B$50 -> 767.22334 | M14: =C14*(Parameters!$B$12/86400)*Parameters!$B$31 -> 33.33312 | N14: =D14*Parameters!$B$37*Parameters!$B$36/Parameters!$B$38 -> 32.62512 | O14: =C14*Parameters!$B$14*Parameters!$B$19/1000 -> 519.2 | P14: =Parameters!$B$32*M14^Parameters!$B$33/1000 -> 342.56661 | Q14: =N14*Parameters!$B$39/1000 -> 175.32739 | R14: =D14*Parameters!$B$42/1000 -> 130 | S14: =C14*Parameters!$B$14*Parameters!$B$45/1000 -> 3.99784 | T14: =L14*Parameters!$B$48/1000 -> 728.86217 | U14: =O14+P14+Q14+R14+S14+T14 -> 1899.954 | V14: =IF(C14=1,Parameters!$B$52,IF(C14=2,Parameters!$B$53,Parameters!$B$54)) -> 109 | W14: =J14*V14/1000 -> 375.5704 | X14: =O14*Parameters!$B$20+P14*Parameters!$B$34+Q14*Parameters!$B$40+R14*Parameters!$B$43+S14*Parameters!$B$46+T14*Parameters!$B$49 -> 58.54513 | Y14: =W14+X14 -> 434.11553 | Z14: =U14*Parameters!$B$8 -> 127.70675 | AA14: =Parameters!$B$8*((Parameters!$B$21*O14+P14+R14+S14)/(1+Parameters!$B$7)^10+Q14/(1+Parameters!$B$7)^15) -> 41.916373 | AB14: =Y14+Z14+AA14 -> 603.73866 | AC14: =AB14*1000/G14 -> 8.2703926
A15: Medium_MG | B15: Medium | C15: 4 | D15: 2 | E15: 0.5 | F15: =C15*Parameters!$B$12 -> 200 | G15: =F15*Parameters!$B$9 -> 73000 | H15: =C15*Parameters!$B$14*Parameters!$B$10/1000 -> 4134.72 | I15: =H15/Parameters!$B$55 -> 4594.1333 | J15: =I15*E15 -> 2297.0667 | K15: =I15*(1-E15) -> 2297.0667 | L15: =K15*1000/Parameters!$B$50 -> 1534.4467 | M15: =C15*(Parameters!$B$12/86400)*Parameters!$B$31 -> 33.33312 | N15: =D15*Parameters!$B$37*Parameters!$B$36/Parameters!$B$38 -> 32.62512 | O15: =C15*Parameters!$B$14*Parameters!$B$19/1000 -> 519.2 | P15: =Parameters!$B$32*M15^Parameters!$B$33/1000 -> 342.56661 | Q15: =N15*Parameters!$B$39/1000 -> 175.32739 | R15: =D15*Parameters!$B$42/1000 -> 130 | S15: =C15*Parameters!$B$14*Parameters!$B$45/1000 -> 3.99784 | T15: =L15*Parameters!$B$48/1000 -> 1457.7243 | U15: =O15+P15+Q15+R15+S15+T15 -> 2628.8162 | V15: =IF(C15=1,Parameters!$B$52,IF(C15=2,Parameters!$B$53,Parameters!$B$54)) -> 109 | W15: =J15*V15/1000 -> 250.38027 | X15: =O15*Parameters!$B$20+P15*Parameters!$B$34+Q15*Parameters!$B$40+R15*Parameters!$B$43+S15*Parameters!$B$46+T15*Parameters!$B$49 -> 70.061152 | Y15: =W15+X15 -> 320.44142 | Z15: =U15*Parameters!$B$8 -> 176.69774 | AA15: =Parameters!$B$8*((Parameters!$B$21*O15+P15+R15+S15)/(1+Parameters!$B$7)^10+Q15/(1+Parameters!$B$7)^15) -> 41.916373 | AB15: =Y15+Z15+AA15 -> 539.05553 | AC15: =AB15*1000/G15 -> 7.3843224
A16: Medium_LG | B16: Medium | C16: 4 | D16: 2 | E16: 0.25 | F16: =C16*Parameters!$B$12 -> 200 | G16: =F16*Parameters!$B$9 -> 73000 | H16: =C16*Parameters!$B$14*Parameters!$B$10/1000 -> 4134.72 | I16: =H16/Parameters!$B$55 -> 4594.1333 | J16: =I16*E16 -> 1148.5333 | K16: =I16*(1-E16) -> 3445.6 | L16: =K16*1000/Parameters!$B$50 -> 2301.67 | M16: =C16*(Parameters!$B$12/86400)*Parameters!$B$31 -> 33.33312 | N16: =D16*Parameters!$B$37*Parameters!$B$36/Parameters!$B$38 -> 32.62512 | O16: =C16*Parameters!$B$14*Parameters!$B$19/1000 -> 519.2 | P16: =Parameters!$B$32*M16^Parameters!$B$33/1000 -> 342.56661 | Q16: =N16*Parameters!$B$39/1000 -> 175.32739 | R16: =D16*Parameters!$B$42/1000 -> 130 | S16: =C16*Parameters!$B$14*Parameters!$B$45/1000 -> 3.99784 | T16: =L16*Parameters!$B$48/1000 -> 2186.5865 | U16: =O16+P16+Q16+R16+S16+T16 -> 3357.6784 | V16: =IF(C16=1,Parameters!$B$52,IF(C16=2,Parameters!$B$53,Parameters!$B$54)) -> 109 | W16: =J16*V16/1000 -> 125.19013 | X16: =O16*Parameters!$B$20+P16*Parameters!$B$34+Q16*Parameters!$B$40+R16*Parameters!$B$43+S16*Parameters!$B$46+T16*Parameters!$B$49 -> 81.577175 | Y16: =W16+X16 -> 206.76731 | Z16: =U16*Parameters!$B$8 -> 225.68873 | AA16: =Parameters!$B$8*((Parameters!$B$21*O16+P16+R16+S16)/(1+Parameters!$B$7)^10+Q16/(1+Parameters!$B$7)^15) -> 41.916373 | AB16: =Y16+Z16+AA16 -> 474.37241 | AC16: =AB16*1000/G16 -> 6.4982522

Sheet Model_Milan
A1: MODEL — North Italy (Milan), yield 1050 kWh/kWp/yr
A2: 12 configurations — all values live-linked to Parameters sheet
A4: Config | B4: Size | C4: N_mod | D4: N_disp | E4: Grid frac | F4: kg/day | G4: H2 [kg/yr] | H4: E_elec [MWh] | I4: E_total [MWh] | J4: E_grid [MWh] | K4: E_PV [MWh] | L4: PV [kWp] | M4: Comp [kW] | N4: Refrig [kW] | O4: CX Elec [k€] | P4: CX Comp [k€] | Q4: CX Refrig [k€] | R4: CX Disp [k€] | S4: CX Water [k€] | T4: CX PV [k€] | U4: CAPEX [k€] | V4: Elec price [€/MWh] | W4: Elec cost [k€/yr] | X4: O&M tot [k€/yr] | Y4: OPEX [k€/yr] | Z4: C_inv,a [k€/yr] | AA4: C_rep,a [k€/yr] | AB4: Total [k€/yr] | AC4: LCOH [€/kg]
A5: Micro_FG | B5: Micro | C5: 1 | D5: 1 | E5: 1 | F5: =C5*Parameters!$B$12 -> 50 | G5: =F5*Parameters!$B$9 -> 18250 | H5: =C5*Parameters!$B$14*Parameters!$B$10/1000 -> 1033.68 | I5: =H5/Parameters!$B$55 -> 1148.5333 | J5: =I5*E5 -> 1148.5333 | K5: =I5*(1-E5) -> 0 | L5: =K5*1000/Parameters!$B$51 -> 0 | M5: =C5*(Parameters!$B$12/86400)*Parameters!$B$31 -> 8.3332799 | N5: =D5*Parameters!$B$37*Parameters!$B$36/Parameters!$B$38 -> 16.31256 | O5: =C5*Parameters!$B$14*Parameters!$B$19/1000 -> 129.8 | P5: =Parameters!$B$32*M5^Parameters!$B$33/1000 -> 152.01193 | Q5: =N5*Parameters!$B$39/1000 -> 87.663697 | R5: =D5*Parameters!$B$42/1000 -> 65 | S5: =C5*Parameters!$B$14*Parameters!$B$45/1000 -> 0.99946 | T5: =L5*Parameters!$B$48/1000 -> 0 | U5: =O5+P5+Q5+R5+S5+T5 -> 435.47509 | V5: =IF(C5=1,Parameters!$B$52,IF(C5=2,Parameters!$B$53,Parameters!$B$54)) -> 129 | W5: =J5*V5/1000 -> 148.1608 | X5: =O5*Parameters!$B$20+P5*Parameters!$B$34+Q5*Parameters!$B$40+R5*Parameters!$B$43+S5*Parameters!$B$46+T5*Parameters!$B$49 -> 19.356855 | Y5: =W5+X5 -> 167.51765 | Z5: =U5*Parameters!$B$8 -> 29.270766 | AA5: =Parameters!$B$8*((Parameters!$B$21*O5+P5+R5+S5)/(1+Parameters!$B$7)^10+Q5/(1+Parameters!$B$7)^15) -> 17.315117 | AB5: =Y5+Z5+AA5 -> 214.10354 | AC5: =AB5*1000/G5 -> 11.731701
A6: Micro_HG | B6: Micro | C6: 1 | D6: 1 | E6: 0.75 | F6: =C6*Parameters!$B$12 -> 50 | G6: =F6*Parameters!$B$9 -> 18250 | H6: =C6*Parameters!$B$14*Parameters!$B$10/1000 -> 1033.68 | I6: =H6/Parameters!$B$55 -> 1148.5333 | J6: =I6*E6 -> 861.4 | K6: =I6*(1-E6) -> 287.13333 | L6: =K6*1000/Parameters!$B$51 -> 209.73947 | M6: =C6*(Parameters!$B$12/86400)*Parameters!$B$31 -> 8.3332799 | N6: =D6*Parameters!$B$37*Parameters!$B$36/Parameters!$B$38 -> 16.31256 | O6: =C6*Parameters!$B$14*Parameters!$B$19/1000 -> 129.8 | P6: =Parameters!$B$32*M6^Parameters!$B$33/1000 -> 152.01193 | Q6: =N6*Parameters!$B$39/1000 -> 87.663697 | R6: =D6*Parameters!$B$42/1000 -> 65 | S6: =C6*Parameters!$B$14*Parameters!$B$45/1000 -> 0.99946 | T6: =L6*Parameters!$B$48/1000 -> 199.2525 | U6: =O6+P6+Q6+R6+S6+T6 -> 634.72758 | V6: =IF(C6=1,Parameters!$B$52,IF(C6=2,Parameters!$B$53,Parameters!$B$54)) -> 129 | W6: =J6*V6/1000 -> 111.1206 | X6: =O6*Parameters!$B$20+P6*Parameters!$B$34+Q6*Parameters!$B$40+R6*Parameters!$B$43+S6*Parameters!$B$46+T6*Parameters!$B$49 -> 22.505044 | Y6: =W6+X6 -> 133.62564 | Z6: =U6*Parameters!$B$8 -> 42.663664 | AA6: =Parameters!$B$8*((Parameters!$B$21*O6+P6+R6+S6)/(1+Parameters!$B$7)^10+Q6/(1+Parameters!$B$7)^15) -> 17.315117 | AB6: =Y6+Z6+AA6 -> 193.60442 | AC6: =AB6*1000/G6 -> 10.608462
A7: Micro_MG | B7: Micro | C7: 1 | D7: 1 | E7: 0.5 | F7: =C7*Parameters!$B$12 -> 50 | G7: =F7*Parameters!$B$9 -> 18250 | H7: =C7*Parameters!$B$14*Parameters!$B$10/1000 -> 1033.68 | I7: =H7/Parameters!$B$55 -> 1148.5333 | J7: =I7*E7 -> 574.26667 | K7: =I7*(1-E7) -> 574.26667 | L7: =K7*1000/Parameters!$B$51 -> 419.47894 | M7: =C7*(Parameters!$B$12/86400)*Parameters!$B$31 -> 8.3332799 | N7: =D7*Parameters!$B$37*Parameters!$B$36/Parameters!$B$38 -> 16.31256 | O7: =C7*Parameters!$B$14*Parameters!$B$19/1000 -> 129.8 | P7: =Parameters!$B$32*M7^Parameters!$B$33/1000 -> 152.01193 | Q7: =N7*Parameters!$B$39/1000 -> 87.663697 | R7: =D7*Parameters!$B$42/1000 -> 65 | S7: =C7*Parameters!$B$14*Parameters!$B$45/1000 -> 0.99946 | T7: =L7*Parameters!$B$48/1000 -> 398.50499 | U7: =O7+P7+Q7+R7+S7+T7 -> 833.98008 | V7: =IF(C7=1,Parameters!$B$52,IF(C7=2,Parameters!$B$53,Parameters!$B$54)) -> 129 | W7: =J7*V7/1000 -> 74.0804 | X7: =O7*Parameters!$B$20+P7*Parameters!$B$34+Q7*Parameters!$B$40+R7*Parameters!$B$43+S7*Parameters!$B$46+T7*Parameters!$B$49 -> 25.653233 | Y7: =W7+X7 -> 99.733633 | Z7: =U7*Parameters!$B$8 -> 56.056561 | AA7: =Parameters!$B$8*((Parameters!$B$21*O7+P7+R7+S7)/(1+Parameters!$B$7)^10+Q7/(1+Parameters!$B$7)^15) -> 17.315117 | AB7: =Y7+Z7+AA7 -> 173.10531 | AC7: =AB7*1000/G7 -> 9.4852225
A8: Micro_LG | B8: Micro | C8: 1 | D8: 1 | E8: 0.25 | F8: =C8*Parameters!$B$12 -> 50 | G8: =F8*Parameters!$B$9 -> 18250 | H8: =C8*Parameters!$B$14*Parameters!$B$10/1000 -> 1033.68 | I8: =H8/Parameters!$B$55 -> 1148.5333 | J8: =I8*E8 -> 287.13333 | K8: =I8*(1-E8) -> 861.4 | L8: =K8*1000/Parameters!$B$51 -> 629.21841 | M8: =C8*(Parameters!$B$12/86400)*Parameters!$B$31 -> 8.3332799 | N8: =D8*Parameters!$B$37*Parameters!$B$36/Parameters!$B$38 -> 16.31256 | O8: =C8*Parameters!$B$14*Parameters!$B$19/1000 -> 129.8 | P8: =Parameters!$B$32*M8^Parameters!$B$33/1000 -> 152.01193 | Q8: =N8*Parameters!$B$39/1000 -> 87.663697 | R8: =D8*Parameters!$B$42/1000 -> 65 | S8: =C8*Parameters!$B$14*Parameters!$B$45/1000 -> 0.99946 | T8: =L8*Parameters!$B$48/1000 -> 597.75749 | U8: =O8+P8+Q8+R8+S8+T8 -> 1033.2326 | V8: =IF(C8=1,Parameters!$B$52,IF(C8=2,Parameters!$B$53,Parameters!$B$54)) -> 129 | W8: =J8*V8/1000 -> 37.0402 | X8: =O8*Parameters!$B$20+P8*Parameters!$B$34+Q8*Parameters!$B$40+R8*Parameters!$B$43+S8*Parameters!$B$46+T8*Parameters!$B$49 -> 28.801423 | Y8: =W8+X8 -> 65.841623 | Z8: =U8*Parameters!$B$8 -> 69.449459 | AA8: =Parameters!$B$8*((Parameters!$B$21*O8+P8+R8+S8)/(1+Parameters!$B$7)^10+Q8/(1+Parameters!$B$7)^15) -> 17.315117 | AB8: =Y8+Z8+AA8 -> 152.6062 | AC8: =AB8*1000/G8 -> 8.3619835
A9: Small_FG | B9: Small | C9: 2 | D9: 2 | E9: 1 | F9: =C9*Parameters!$B$12 -> 100 | G9: =F9*Parameters!$B$9 -> 36500 | H9: =C9*Parameters!$B$14*Parameters!$B$10/1000 -> 2067.36 | I9: =H9/Parameters!$B$55 -> 2297.0667 | J9: =I9*E9 -> 2297.0667 | K9: =I9*(1-E9) -> 0 | L9: =K9*1000/Parameters!$B$51 -> 0 | M9: =C9*(Parameters!$B$12/86400)*Parameters!$B$31 -> 16.66656 | N9: =D9*Parameters!$B$37*Parameters!$B$36/Parameters!$B$38 -> 32.62512 | O9: =C9*Parameters!$B$14*Parameters!$B$19/1000 -> 259.6 | P9: =Parameters!$B$32*M9^Parameters!$B$33/1000 -> 228.19775 | Q9: =N9*Parameters!$B$39/1000 -> 175.32739 | R9: =D9*Parameters!$B$42/1000 -> 130 | S9: =C9*Parameters!$B$14*Parameters!$B$45/1000 -> 1.99892 | T9: =L9*Parameters!$B$48/1000 -> 0 | U9: =O9+P9+Q9+R9+S9+T9 -> 795.12406 | V9: =IF(C9=1,Parameters!$B$52,IF(C9=2,Parameters!$B$53,Parameters!$B$54)) -> 119 | W9: =J9*V9/1000 -> 273.35093 | X9: =O9*Parameters!$B$20+P9*Parameters!$B$34+Q9*Parameters!$B$40+R9*Parameters!$B$43+S9*Parameters!$B$46+T9*Parameters!$B$49 -> 32.64762 | Y9: =W9+X9 -> 305.99855 | Z9: =U9*Parameters!$B$8 -> 53.444826 | AA9: =Parameters!$B$8*((Parameters!$B$21*O9+P9+R9+S9)/(1+Parameters!$B$7)^10+Q9/(1+Parameters!$B$7)^15) -> 30.837806 | AB9: =Y9+Z9+AA9 -> 390.28119 | AC9: =AB9*1000/G9 -> 10.692635
A10: Small_HG | B10: Small | C10: 2 | D10: 2 | E10: 0.75 | F10: =C10*Parameters!$B$12 -> 100 | G10: =F10*Parameters!$B$9 -> 36500 | H10: =C10*Parameters!$B$14*Parameters!$B$10/1000 -> 2067.36 | I10: =H10/Parameters!$B$55 -> 2297.0667 | J10: =I10*E10 -> 1722.8 | K10: =I10*(1-E10) -> 574.26667 | L10: =K10*1000/Parameters!$B$51 -> 419.47894 | M10: =C10*(Parameters!$B$12/86400)*Parameters!$B$31 -> 16.66656 | N10: =D10*Parameters!$B$37*Parameters!$B$36/Parameters!$B$38 -> 32.62512 | O10: =C10*Parameters!$B$14*Parameters!$B$19/1000 -> 259.6 | P10: =Parameters!$B$32*M10^Parameters!$B$33/1000 -> 228.19775 | Q10: =N10*Parameters!$B$39/1000 -> 175.32739 | R10: =D10*Parameters!$B$42/1000 -> 130 | S10: =C10*Parameters!$B$14*Parameters!$B$45/1000 -> 1.99892 | T10: =L10*Parameters!$B$48/1000 -> 398.50499 | U10: =O10+P10+Q10+R10+S10+T10 -> 1193.6291 | V10: =IF(C10=1,Parameters!$B$52,IF(C10=2,Parameters!$B$53,Parameters!$B$54)) -> 119 | W10: =J10*V10/1000 -> 205.0132 | X10: =O10*Parameters!$B$20+P10*Parameters!$B$34+Q10*Parameters!$B$40+R10*Parameters!$B$43+S10*Parameters!$B$46+T10*Parameters!$B$49 -> 38.943999 | Y10: =W10+X10 -> 243.9572 | Z10: =U10*Parameters!$B$8 -> 80.230621 | AA10: =Parameters!$B$8*((Parameters!$B$21*O10+P10+R10+S10)/(1+Parameters!$B$7)^10+Q10/(1+Parameters!$B$7)^15) -> 30.837806 | AB10: =Y10+Z10+AA10 -> 355.02563 | AC10: =AB10*1000/G10 -> 9.7267295
A11: Small_MG | B11: Small | C11: 2 | D11: 2 | E11: 0.5 | F11: =C11*Parameters!$B$12 -> 100 | G11: =F11*Parameters!$B$9 -> 36500 | H11: =C11*Parameters!$B$14*Parameters!$B$10/1000 -> 2067.36 | I11: =H11/Parameters!$B$55 -> 2297.0667 | J11: =I11*E11 -> 1148.5333 | K11: =I11*(1-E11) -> 1148.5333 | L11: =K11*1000/Parameters!$B$51 -> 838.95788 | M11: =C11*(Parameters!$B$12/86400)*Parameters!$B$31 -> 16.66656 | N11: =D11*Parameters!$B$37*Parameters!$B$36/Parameters!$B$38 -> 32.62512 | O11: =C11*Parameters!$B$14*Parameters!$B$19/1000 -> 259.6 | P11: =Parameters!$B$32*M11^Parameters!$B$33/1000 -> 228.19775 | Q11: =N11*Parameters!$B$39/1000 -> 175.32739 | R11: =D11*Parameters!$B$42/1000 -> 130 | S11: =C11*Parameters!$B$14*Parameters!$B$45/1000 -> 1.99892 | T11: =L11*Parameters!$B$48/1000 -> 797.00998 | U11: =O11+P11+Q11+R11+S11+T11 -> 1592.134 | V11: =IF(C11=1,Parameters!$B$52,IF(C11=2,Parameters!$B$53,Parameters!$B$54)) -> 119 | W11: =J11*V11/1000 -> 136.67547 | X11: =O11*Parameters!$B$20+P11*Parameters!$B$34+Q11*Parameters!$B$40+R11*Parameters!$B$43+S11*Parameters!$B$46+T11*Parameters!$B$49 -> 45.240378 | Y11: =W11+X11 -> 181.91584 | Z11: =U11*Parameters!$B$8 -> 107.01642 | AA11: =Parameters!$B$8*((Parameters!$B$21*O11+P11+R11+S11)/(1+Parameters!$B$7)^10+Q11/(1+Parameters!$B$7)^15) -> 30.837806 | AB11: =Y11+Z11+AA11 -> 319.77007 | AC11: =AB11*1000/G11 -> 8.7608237
A12: Small_LG | B12: Small | C12: 2 | D12: 2 | E12: 0.25 | F12: =C12*Parameters!$B$12 -> 100 | G12: =F12*Parameters!$B$9 -> 36500 | H12: =C12*Parameters!$B$14*Parameters!$B$10/1000 -> 2067.36 | I12: =H12/Parameters!$B$55 -> 2297.0667 | J12: =I12*E12 -> 574.26667 | K12: =I12*(1-E12) -> 1722.8 | L12: =K12*1000/Parameters!$B$51 -> 1258.4368 | M12: =C12*(Parameters!$B$12/86400)*Parameters!$B$31 -> 16.66656 | N12: =D12*Parameters!$B$37*Parameters!$B$36/Parameters!$B$38 -> 32.62512 | O12: =C12*Parameters!$B$14*Parameters!$B$19/1000 -> 259.6 | P12: =Parameters!$B$32*M12^Parameters!$B$33/1000 -> 228.19775 | Q12: =N12*Parameters!$B$39/1000 -> 175.32739 | R12: =D12*Parameters!$B$42/1000 -> 130 | S12: =C12*Parameters!$B$14*Parameters!$B$45/1000 -> 1.99892 | T12: =L12*Parameters!$B$48/1000 -> 1195.515 | U12: =O12+P12+Q12+R12+S12+T12 -> 1990.639 | V12: =IF(C12=1,Parameters!$B$52,IF(C12=2,Parameters!$B$53,Parameters!$B$54)) -> 119 | W12: =J12*V12/1000 -> 68.337733 | X12: =O12*Parameters!$B$20+P12*Parameters!$B$34+Q12*Parameters!$B$40+R12*Parameters!$B$43+S12*Parameters!$B$46+T12*Parameters!$B$49 -> 51.536757 | Y12: =W12+X12 -> 119.87449 | Z12: =U12*Parameters!$B$8 -> 133.80221 | AA12: =Parameters!$B$8*((Parameters!$B$21*O12+P12+R12+S12)/(1+Parameters!$B$7)^10+Q12/(1+Parameters!$B$7)^15) -> 30.837806 | AB12: =Y12+Z12+AA12 -> 284.51451 | AC12: =AB12*1000/G12 -> 7.794918
A13: Medium_FG | B13: Medium | C13: 4 | D13: 2 | E13: 1 | F13: =C13*Parameters!$B$12 -> 200 | G13: =F13*Parameters!$B$9 -> 73000 | H13: =C13*Parameters!$B$14*Parameters!$B$10/1000 -> 4134.72 | I13: =H13/Parameters!$B$55 -> 4594.1333 | J13: =I13*E13 -> 4594.1333 | K13: =I13*(1-E13) -> 0 | L13: =K13*1000/Parameters!$B$51 -> 0 | M13: =C13*(Parameters!$B$12/86400)*Parameters!$B$31 -> 33.33312 | N13: =D13*Parameters!$B$37*Parameters!$B$36/Parameters!$B$38 -> 32.62512 | O13: =C13*Parameters!$B$14*Parameters!$B$19/1000 -> 519.2 | P13: =Parameters!$B$32*M13^Parameters!$B$33/1000 -> 342.56661 | Q13: =N13*Parameters!$B$39/1000 -> 175.32739 | R13: =D13*Parameters!$B$42/1000 -> 130 | S13: =C13*Parameters!$B$14*Parameters!$B$45/1000 -> 3.99784 | T13: =L13*Parameters!$B$48/1000 -> 0 | U13: =O13+P13+Q13+R13+S13+T13 -> 1171.0918 | V13: =IF(C13=1,Parameters!$B$52,IF(C13=2,Parameters!$B$53,Parameters!$B$54)) -> 109 | W13: =J13*V13/1000 -> 500.76053 | X13: =O13*Parameters!$B$20+P13*Parameters!$B$34+Q13*Parameters!$B$40+R13*Parameters!$B$43+S13*Parameters!$B$46+T13*Parameters!$B$49 -> 47.029108 | Y13: =W13+X13 -> 547.78964 | Z13: =U13*Parameters!$B$8 -> 78.715767 | AA13: =Parameters!$B$8*((Parameters!$B$21*O13+P13+R13+S13)/(1+Parameters!$B$7)^10+Q13/(1+Parameters!$B$7)^15) -> 41.916373 | AB13: =Y13+Z13+AA13 -> 668.42178 | AC13: =AB13*1000/G13 -> 9.1564628
A14: Medium_HG | B14: Medium | C14: 4 | D14: 2 | E14: 0.75 | F14: =C14*Parameters!$B$12 -> 200 | G14: =F14*Parameters!$B$9 -> 73000 | H14: =C14*Parameters!$B$14*Parameters!$B$10/1000 -> 4134.72 | I14: =H14/Parameters!$B$55 -> 4594.1333 | J14: =I14*E14 -> 3445.6 | K14: =I14*(1-E14) -> 1148.5333 | L14: =K14*1000/Parameters!$B$51 -> 838.95788 | M14: =C14*(Parameters!$B$12/86400)*Parameters!$B$31 -> 33.33312 | N14: =D14*Parameters!$B$37*Parameters!$B$36/Parameters!$B$38 -> 32.62512 | O14: =C14*Parameters!$B$14*Parameters!$B$19/1000 -> 519.2 | P14: =Parameters!$B$32*M14^Parameters!$B$33/1000 -> 342.56661 | Q14: =N14*Parameters!$B$39/1000 -> 175.32739 | R14: =D14*Parameters!$B$42/1000 -> 130 | S14: =C14*Parameters!$B$14*Parameters!$B$45/1000 -> 3.99784 | T14: =L14*Parameters!$B$48/1000 -> 797.00998 | U14: =O14+P14+Q14+R14+S14+T14 -> 1968.1018 | V14: =IF(C14=1,Parameters!$B$52,IF(C14=2,Parameters!$B$53,Parameters!$B$54)) -> 109 | W14: =J14*V14/1000 -> 375.5704 | X14: =O14*Parameters!$B$20+P14*Parameters!$B$34+Q14*Parameters!$B$40+R14*Parameters!$B$43+S14*Parameters!$B$46+T14*Parameters!$B$49 -> 59.621865 | Y14: =W14+X14 -> 435.19227 | Z14: =U14*Parameters!$B$8 -> 132.28736 | AA14: =Parameters!$B$8*((Parameters!$B$21*O14+P14+R14+S14)/(1+Parameters!$B$7)^10+Q14/(1+Parameters!$B$7)^15) -> 41.916373 | AB14: =Y14+Z14+AA14 -> 609.396 | AC14: =AB14*1000/G14 -> 8.3478904
A15: Medium_MG | B15: Medium | C15: 4 | D15: 2 | E15: 0.5 | F15: =C15*Parameters!$B$12 -> 200 | G15: =F15*Parameters!$B$9 -> 73000 | H15: =C15*Parameters!$B$14*Parameters!$B$10/1000 -> 4134.72 | I15: =H15/Parameters!$B$55 -> 4594.1333 | J15: =I15*E15 -> 2297.0667 | K15: =I15*(1-E15) -> 2297.0667 | L15: =K15*1000/Parameters!$B$51 -> 1677.9158 | M15: =C15*(Parameters!$B$12/86400)*Parameters!$B$31 -> 33.33312 | N15: =D15*Parameters!$B$37*Parameters!$B$36/Parameters!$B$38 -> 32.62512 | O15: =C15*Parameters!$B$14*Parameters!$B$19/1000 -> 519.2 | P15: =Parameters!$B$32*M15^Parameters!$B$33/1000 -> 342.56661 | Q15: =N15*Parameters!$B$39/1000 -> 175.32739 | R15: =D15*Parameters!$B$42/1000 -> 130 | S15: =C15*Parameters!$B$14*Parameters!$B$45/1000 -> 3.99784 | T15: =L15*Parameters!$B$48/1000 -> 1594.02 | U15: =O15+P15+Q15+R15+S15+T15 -> 2765.1118 | V15: =IF(C15=1,Parameters!$B$52,IF(C15=2,Parameters!$B$53,Parameters!$B$54)) -> 109 | W15: =J15*V15/1000 -> 250.38027 | X15: =O15*Parameters!$B$20+P15*Parameters!$B$34+Q15*Parameters!$B$40+R15*Parameters!$B$43+S15*Parameters!$B$46+T15*Parameters!$B$49 -> 72.214623 | Y15: =W15+X15 -> 322.59489 | Z15: =U15*Parameters!$B$8 -> 185.85895 | AA15: =Parameters!$B$8*((Parameters!$B$21*O15+P15+R15+S15)/(1+Parameters!$B$7)^10+Q15/(1+Parameters!$B$7)^15) -> 41.916373 | AB15: =Y15+Z15+AA15 -> 550.37021 | AC15: =AB15*1000/G15 -> 7.5393179
A16: Medium_LG | B16: Medium | C16: 4 | D16: 2 | E16: 0.25 | F16: =C16*Parameters!$B$12 -> 200 | G16: =F16*Parameters!$B$9 -> 73000 | H16: =C16*Parameters!$B$14*Parameters!$B$10/1000 -> 4134.72 | I16: =H16/Parameters!$B$55 -> 4594.1333 | J16: =I16*E16 -> 1148.5333 | K16: =I16*(1-E16) -> 3445.6 | L16: =K16*1000/Parameters!$B$51 -> 2516.8736 | M16: =C16*(Parameters!$B$12/86400)*Parameters!$B$31 -> 33.33312 | N16: =D16*Parameters!$B$37*Parameters!$B$36/Parameters!$B$38 -> 32.62512 | O16: =C16*Parameters!$B$14*Parameters!$B$19/1000 -> 519.2 | P16: =Parameters!$B$32*M16^Parameters!$B$33/1000 -> 342.56661 | Q16: =N16*Parameters!$B$39/1000 -> 175.32739 | R16: =D16*Parameters!$B$42/1000 -> 130 | S16: =C16*Parameters!$B$14*Parameters!$B$45/1000 -> 3.99784 | T16: =L16*Parameters!$B$48/1000 -> 2391.0299 | U16: =O16+P16+Q16+R16+S16+T16 -> 3562.1218 | V16: =IF(C16=1,Parameters!$B$52,IF(C16=2,Parameters!$B$53,Parameters!$B$54)) -> 109 | W16: =J16*V16/1000 -> 125.19013 | X16: =O16*Parameters!$B$20+P16*Parameters!$B$34+Q16*Parameters!$B$40+R16*Parameters!$B$43+S16*Parameters!$B$46+T16*Parameters!$B$49 -> 84.807381 | Y16: =W16+X16 -> 209.99751 | Z16: =U16*Parameters!$B$8 -> 239.43054 | AA16: =Parameters!$B$8*((Parameters!$B$21*O16+P16+R16+S16)/(1+Parameters!$B$7)^10+Q16/(1+Parameters!$B$7)^15) -> 41.916373 | AB16: =Y16+Z16+AA16 -> 491.34442 | AC16: =AB16*1000/G16 -> 6.7307455

Sheet Results
A1: LCOH RESULTS SUMMARY (€/kg H2)
A3: A) NAPLES (South Italy)
A4: Plant Size | B4: Full Grid 100% | C4: High Grid 75% | D4: Mid Grid 50% | E4: Low Grid 25%
A5: Micro (50 kg/d) | B5: =Model_Naples!AC5 -> 11.731701 | C5: =Model_Naples!AC6 -> 10.530964 | D5: =Model_Naples!AC7 -> 9.3302269 | E5: =Model_Naples!AC8 -> 8.1294901
A6: Small (100 kg/d) | B6: =Model_Naples!AC9 -> 10.692635 | C6: =Model_Naples!AC10 -> 9.6492317 | D6: =Model_Naples!AC11 -> 8.6058282 | E6: =Model_Naples!AC12 -> 7.5624246
A7: Medium (200 kg/d) | B7: =Model_Naples!AC13 -> 9.1564628 | C7: =Model_Naples!AC14 -> 8.2703926 | D7: =Model_Naples!AC15 -> 7.3843224 | E7: =Model_Naples!AC16 -> 6.4982522
A10: B) MILAN (North Italy)
A11: Plant Size | B11: Full Grid 100% | C11: High Grid 75% | D11: Mid Grid 50% | E11: Low Grid 25%
A12: Micro (50 kg/d) | B12: =Model_Milan!AC5 -> 11.731701 | C12: =Model_Milan!AC6 -> 10.608462 | D12: =Model_Milan!AC7 -> 9.4852225 | E12: =Model_Milan!AC8 -> 8.3619835
A13: Small (100 kg/d) | B13: =Model_Milan!AC9 -> 10.692635 | C13: =Model_Milan!AC10 -> 9.7267295 | D13: =Model_Milan!AC11 -> 8.7608237 | E13: =Model_Milan!AC12 -> 7.794918
A14: Medium (200 kg/d) | B14: =Model_Milan!AC13 -> 9.1564628 | C14: =Model_Milan!AC14 -> 8.3478904 | D14: =Model_Milan!AC15 -> 7.5393179 | E14: =Model_Milan!AC16 -> 6.7307455
A18: KEY FINDINGS
A19: Best configuration | B19: =CONCATENATE("Medium_LG, Naples = ",TEXT(Model_Naples!AC16,"0.00")," EUR/kg") -> Medium_LG, Naples = 6.50 EUR/kg
A20: Worst configuration | B20: =CONCATENATE("Micro_FG, Naples = ",TEXT(Model_Naples!AC5,"0.00")," EUR/kg") -> Micro_FG, Naples = 11.73 EUR/kg
A21: Range (worst -> best) | B21: =CONCATENATE(TEXT((Model_Naples!AC16-Model_Naples!AC5)/Model_Naples!AC5*100,"0.0"),"%") -> -44.6%
A22: Scale effect Micro->Medium (LG) | B22: =CONCATENATE(TEXT((Model_Naples!AC16-Model_Naples!AC8)/Model_Naples!AC8*100,"0.0"),"%") -> -20.1%
A23: Milan penalty (Medium_LG) | B23: =CONCATENATE(TEXT((Model_Milan!AC16-Model_Naples!AC16)/Model_Naples!AC16*100,"0.0"),"%") -> 3.6%
A26: COST BREAKDOWN - Best config (Medium_LG, Naples)
A27: Component | B27: k€/yr | C27: % of total
A28: Annualised CAPEX | B28: =Model_Naples!Z16 -> 225.68873 | C28: =B28/B32 -> 0.47576276
A29: Annualised REPLEX | B29: =Model_Naples!AA16 -> 41.916373 | C29: =B29/B32 -> 0.088361743
A30: OPEX - grid electricity | B30: =Model_Naples!W16 -> 125.19013 | C30: =B30/B32 -> 0.26390686
A31: OPEX - O&M | B31: =Model_Naples!X16 -> 81.577175 | C31: =B31/B32 -> 0.17196863
A32: TOTAL | B32: =SUM(B28:B31) -> 474.37241

Sheet Sensitivity
A1: SENSITIVITY ANALYSIS — Reference: Medium_MG (200 kg/day, 50% grid, Naples)
A3: 1) Electrolyzer specific consumption
A4: Spec cons [kWh/Nm3] | B4: Efficiency | C4: Power/mod [kW] | D4: E_elec [MWh] | E4: E_total [MWh] | F4: E_grid [MWh] | G4: E_PV [MWh] | H4: CX elec [k€] | I4: CX water [k€] | J4: CX PV [k€] | K4: CAPEX [k€] | L4: Elec cost [k€] | M4: O&M [k€] | N4: C_inv,a | O4: C_rep,a | P4: OPEX | Q4: Total [k€] | R4: LCOH [€/kg]
A5: 4 | B5: =Parameters!$B$17/(A5/Parameters!$B$16) -> 0.73425 | C5: =A5*Parameters!$B$13 -> 92 | D5: =4*C5*Parameters!$B$10/1000 -> 3223.68 | E5: =D5/Parameters!$B$55 -> 3581.8667 | F5: =E5*0.5 -> 1790.9333 | G5: =E5*0.5 -> 1790.9333 | H5: =4*C5*Parameters!$B$19/1000 -> 404.8 | I5: =4*C5*Parameters!$B$45/1000 -> 3.11696 | J5: =G5*1000/Parameters!$B$50*Parameters!$B$48/1000 -> 1136.5308 | K5: =H5+I5+J5+Model_Naples!P15+Model_Naples!Q15+Model_Naples!R15 -> 2192.3418 | L5: =F5*Parameters!$B$54/1000 -> 195.21173 | M5: =H5*Parameters!$B$20+Model_Naples!P15*Parameters!$B$34+Model_Naples!Q15*Parameters!$B$40+Model_Naples!R15*Parameters!$B$43+I5*Parameters!$B$46+J5*Parameters!$B$49 -> 62.680677 | N5: =K5*Parameters!$B$8 -> 147.35981 | O5: =Parameters!$B$8*((Parameters!$B$21*H5+Model_Naples!P15+Model_Naples!R15+I5)/(1+Parameters!$B$7)^10+Model_Naples!Q15/(1+Parameters!$B$7)^15) -> 39.55503 | P5: =L5+M5 -> 257.89241 | Q5: =N5+O5+P5 -> 444.80725 | R5: =Q5*1000/73000 -> 6.09325
A6: 4.5 | B6: =Parameters!$B$17/(A6/Parameters!$B$16) -> 0.65266667 | C6: =A6*Parameters!$B$13 -> 103.5 | D6: =4*C6*Parameters!$B$10/1000 -> 3626.64 | E6: =D6/Parameters!$B$55 -> 4029.6 | F6: =E6*0.5 -> 2014.8 | G6: =E6*0.5 -> 2014.8 | H6: =4*C6*Parameters!$B$19/1000 -> 455.4 | I6: =4*C6*Parameters!$B$45/1000 -> 3.50658 | J6: =G6*1000/Parameters!$B$50*Parameters!$B$48/1000 -> 1278.5972 | K6: =H6+I6+J6+Model_Naples!P15+Model_Naples!Q15+Model_Naples!R15 -> 2385.3978 | L6: =F6*Parameters!$B$54/1000 -> 219.6132 | M6: =H6*Parameters!$B$20+Model_Naples!P15*Parameters!$B$34+Model_Naples!Q15*Parameters!$B$40+Model_Naples!R15*Parameters!$B$43+I6*Parameters!$B$46+J6*Parameters!$B$49 -> 65.945118 | N6: =K6*Parameters!$B$8 -> 160.3362 | O6: =Parameters!$B$8*((Parameters!$B$21*H6+Model_Naples!P15+Model_Naples!R15+I6)/(1+Parameters!$B$7)^10+Model_Naples!Q15/(1+Parameters!$B$7)^15) -> 40.59947 | P6: =L6+M6 -> 285.55832 | Q6: =N6+O6+P6 -> 486.49399 | R6: =Q6*1000/73000 -> 6.6643012
A7: 4.8 | B7: =Parameters!$B$17/(A7/Parameters!$B$16) -> 0.611875 | C7: =A7*Parameters!$B$13 -> 110.4 | D7: =4*C7*Parameters!$B$10/1000 -> 3868.416 | E7: =D7/Parameters!$B$55 -> 4298.24 | F7: =E7*0.5 -> 2149.12 | G7: =E7*0.5 -> 2149.12 | H7: =4*C7*Parameters!$B$19/1000 -> 485.76 | I7: =4*C7*Parameters!$B$45/1000 -> 3.740352 | J7: =G7*1000/Parameters!$B$50*Parameters!$B$48/1000 -> 1363.837 | K7: =H7+I7+J7+Model_Naples!P15+Model_Naples!Q15+Model_Naples!R15 -> 2501.2314 | L7: =F7*Parameters!$B$54/1000 -> 234.25408 | M7: =H7*Parameters!$B$20+Model_Naples!P15*Parameters!$B$34+Model_Naples!Q15*Parameters!$B$40+Model_Naples!R15*Parameters!$B$43+I7*Parameters!$B$46+J7*Parameters!$B$49 -> 67.903783 | N7: =K7*Parameters!$B$8 -> 168.12204 | O7: =Parameters!$B$8*((Parameters!$B$21*H7+Model_Naples!P15+Model_Naples!R15+I7)/(1+Parameters!$B$7)^10+Model_Naples!Q15/(1+Parameters!$B$7)^15) -> 41.226134 | P7: =L7+M7 -> 302.15786 | Q7: =N7+O7+P7 -> 511.50603 | R7: =Q7*1000/73000 -> 7.006932
A8: 5.1 | B8: =Parameters!$B$17/(A8/Parameters!$B$16) -> 0.57588235 | C8: =A8*Parameters!$B$13 -> 117.3 | D8: =4*C8*Parameters!$B$10/1000 -> 4110.192 | E8: =D8/Parameters!$B$55 -> 4566.88 | F8: =E8*0.5 -> 2283.44 | G8: =E8*0.5 -> 2283.44 | H8: =4*C8*Parameters!$B$19/1000 -> 516.12 | I8: =4*C8*Parameters!$B$45/1000 -> 3.974124 | J8: =G8*1000/Parameters!$B$50*Parameters!$B$48/1000 -> 1449.0768 | K8: =H8+I8+J8+Model_Naples!P15+Model_Naples!Q15+Model_Naples!R15 -> 2617.065 | L8: =F8*Parameters!$B$54/1000 -> 248.89496 | M8: =H8*Parameters!$B$20+Model_Naples!P15*Parameters!$B$34+Model_Naples!Q15*Parameters!$B$40+Model_Naples!R15*Parameters!$B$43+I8*Parameters!$B$46+J8*Parameters!$B$49 -> 69.862447 | N8: =K8*Parameters!$B$8 -> 175.90787 | O8: =Parameters!$B$8*((Parameters!$B$21*H8+Model_Naples!P15+Model_Naples!R15+I8)/(1+Parameters!$B$7)^10+Model_Naples!Q15/(1+Parameters!$B$7)^15) -> 41.852798 | P8: =L8+M8 -> 318.75741 | Q8: =N8+O8+P8 -> 536.51808 | R8: =Q8*1000/73000 -> 7.3495627
A9: 5.5 | B9: =Parameters!$B$17/(A9/Parameters!$B$16) -> 0.534 | C9: =A9*Parameters!$B$13 -> 126.5 | D9: =4*C9*Parameters!$B$10/1000 -> 4432.56 | E9: =D9/Parameters!$B$55 -> 4925.0667 | F9: =E9*0.5 -> 2462.5333 | G9: =E9*0.5 -> 2462.5333 | H9: =4*C9*Parameters!$B$19/1000 -> 556.6 | I9: =4*C9*Parameters!$B$45/1000 -> 4.28582 | J9: =G9*1000/Parameters!$B$50*Parameters!$B$48/1000 -> 1562.7299 | K9: =H9+I9+J9+Model_Naples!P15+Model_Naples!Q15+Model_Naples!R15 -> 2771.5097 | L9: =F9*Parameters!$B$54/1000 -> 268.41613 | M9: =H9*Parameters!$B$20+Model_Naples!P15*Parameters!$B$34+Model_Naples!Q15*Parameters!$B$40+Model_Naples!R15*Parameters!$B$43+I9*Parameters!$B$46+J9*Parameters!$B$49 -> 72.474 | N9: =K9*Parameters!$B$8 -> 186.28899 | O9: =Parameters!$B$8*((Parameters!$B$21*H9+Model_Naples!P15+Model_Naples!R15+I9)/(1+Parameters!$B$7)^10+Model_Naples!Q15/(1+Parameters!$B$7)^15) -> 42.68835 | P9: =L9+M9 -> 340.89013 | Q9: =N9+O9+P9 -> 569.86747 | R9: =Q9*1000/73000 -> 7.8064037
A10: 6 | B10: =Parameters!$B$17/(A10/Parameters!$B$16) -> 0.4895 | C10: =A10*Parameters!$B$13 -> 138 | D10: =4*C10*Parameters!$B$10/1000 -> 4835.52 | E10: =D10/Parameters!$B$55 -> 5372.8 | F10: =E10*0.5 -> 2686.4 | G10: =E10*0.5 -> 2686.4 | H10: =4*C10*Parameters!$B$19/1000 -> 607.2 | I10: =4*C10*Parameters!$B$45/1000 -> 4.67544 | J10: =G10*1000/Parameters!$B$50*Parameters!$B$48/1000 -> 1704.7963 | K10: =H10+I10+J10+Model_Naples!P15+Model_Naples!Q15+Model_Naples!R15 -> 2964.5657 | L10: =F10*Parameters!$B$54/1000 -> 292.8176 | M10: =H10*Parameters!$B$20+Model_Naples!P15*Parameters!$B$34+Model_Naples!Q15*Parameters!$B$40+Model_Naples!R15*Parameters!$B$43+I10*Parameters!$B$46+J10*Parameters!$B$49 -> 75.738441 | N10: =K10*Parameters!$B$8 -> 199.26538 | O10: =Parameters!$B$8*((Parameters!$B$21*H10+Model_Naples!P15+Model_Naples!R15+I10)/(1+Parameters!$B$7)^10+Model_Naples!Q15/(1+Parameters!$B$7)^15) -> 43.73279 | P10: =L10+M10 -> 368.55604 | Q10: =N10+O10+P10 -> 611.55421 | R10: =Q10*1000/73000 -> 8.377455
A12: 2) Grid electricity price (Medium_MG, spec=5.1)
A13: Price [€/MWh] | B13: LCOH [€/kg] | C13: Change vs base
A14: 70 | B14: =(Model_Naples!Z15+Model_Naples!AA15+Model_Naples!X15+Model_Naples!J15*A14/1000)*1000/73000 -> 6.1571224 | C14: =B14-$B$16 -> -1.2272
A15: 90 | B15: =(Model_Naples!Z15+Model_Naples!AA15+Model_Naples!X15+Model_Naples!J15*A15/1000)*1000/73000 -> 6.7864557 | C15: =B15-$B$16 -> -0.59786667
A16: 109 | B16: =(Model_Naples!Z15+Model_Naples!AA15+Model_Naples!X15+Model_Naples!J15*A16/1000)*1000/73000 -> 7.3843224 | C16: =B16-$B$16 -> 0
A17: 130 | B17: =(Model_Naples!Z15+Model_Naples!AA15+Model_Naples!X15+Model_Naples!J15*A17/1000)*1000/73000 -> 8.0451224 | C17: =B17-$B$16 -> 0.6608
A18: 150 | B18: =(Model_Naples!Z15+Model_Naples!AA15+Model_Naples!X15+Model_Naples!J15*A18/1000)*1000/73000 -> 8.6744557 | C18: =B18-$B$16 -> 1.2901333
A19: 180 | B19: =(Model_Naples!Z15+Model_Naples!AA15+Model_Naples!X15+Model_Naples!J15*A19/1000)*1000/73000 -> 9.6184557 | C19: =B19-$B$16 -> 2.2341333

Sheet CO2_Intensity
A1: CARBON INTENSITY (optional analysis) — kg CO2 / kg H2
A3: Grid carbon intensity | B3: 250 | C3: gCO2/kWh (Italy 200-300)
A4: PV carbon intensity | B4: 35 | C4: gCO2/kWh (LCA ~30-40)
A6: Config | B6: E_grid [MWh] | C6: E_PV [MWh] | D6: H2 [kg/yr] | E6: CO2 [kg/kg H2]
A7: Micro_FG | B7: =Model_Naples!J5 -> 1148.5333 | C7: =Model_Naples!K5 -> 0 | D7: =Model_Naples!G5 -> 18250 | E7: =(B7*$B$3+C7*$B$4)/D7 -> 15.733333
A8: Micro_HG | B8: =Model_Naples!J6 -> 861.4 | C8: =Model_Naples!K6 -> 287.13333 | D8: =Model_Naples!G6 -> 18250 | E8: =(B8*$B$3+C8*$B$4)/D8 -> 12.350667
A9: Micro_MG | B9: =Model_Naples!J7 -> 574.26667 | C9: =Model_Naples!K7 -> 574.26667 | D9: =Model_Naples!G7 -> 18250 | E9: =(B9*$B$3+C9*$B$4)/D9 -> 8.968
A10: Micro_LG | B10: =Model_Naples!J8 -> 287.13333 | C10: =Model_Naples!K8 -> 861.4 | D10: =Model_Naples!G8 -> 18250 | E10: =(B10*$B$3+C10*$B$4)/D10 -> 5.5853333
A11: Small_FG | B11: =Model_Naples!J9 -> 2297.0667 | C11: =Model_Naples!K9 -> 0 | D11: =Model_Naples!G9 -> 36500 | E11: =(B11*$B$3+C11*$B$4)/D11 -> 15.733333
A12: Small_HG | B12: =Model_Naples!J10 -> 1722.8 | C12: =Model_Naples!K10 -> 574.26667 | D12: =Model_Naples!G10 -> 36500 | E12: =(B12*$B$3+C12*$B$4)/D12 -> 12.350667
A13: Small_MG | B13: =Model_Naples!J11 -> 1148.5333 | C13: =Model_Naples!K11 -> 1148.5333 | D13: =Model_Naples!G11 -> 36500 | E13: =(B13*$B$3+C13*$B$4)/D13 -> 8.968
A14: Small_LG | B14: =Model_Naples!J12 -> 574.26667 | C14: =Model_Naples!K12 -> 1722.8 | D14: =Model_Naples!G12 -> 36500 | E14: =(B14*$B$3+C14*$B$4)/D14 -> 5.5853333
A15: Medium_FG | B15: =Model_Naples!J13 -> 4594.1333 | C15: =Model_Naples!K13 -> 0 | D15: =Model_Naples!G13 -> 73000 | E15: =(B15*$B$3+C15*$B$4)/D15 -> 15.733333
A16: Medium_HG | B16: =Model_Naples!J14 -> 3445.6 | C16: =Model_Naples!K14 -> 1148.5333 | D16: =Model_Naples!G14 -> 73000 | E16: =(B16*$B$3+C16*$B$4)/D16 -> 12.350667
A17: Medium_MG | B17: =Model_Naples!J15 -> 2297.0667 | C17: =Model_Naples!K15 -> 2297.0667 | D17: =Model_Naples!G15 -> 73000 | E17: =(B17*$B$3+C17*$B$4)/D17 -> 8.968
A18: Medium_LG | B18: =Model_Naples!J16 -> 1148.5333 | C18: =Model_Naples!K16 -> 3445.6 | D18: =Model_Naples!G16 -> 73000 | E18: =(B18*$B$3+C18*$B$4)/D18 -> 5.5853333
